<?xml version="1.0" encoding="utf-8"?>

<robot name="spmr02">
  <link name="base_link">
    <inertial>
      <origin xyz="0.036333 3.2862E-05 0.086193" rpy="0 0 0" />
      <mass value="37.767" />
      <inertia ixx="1.9204" ixy="-2.4093E-16" ixz="-0.0004014" iyy="3.0624" iyz="1.9122E-14" izz="4.7207" />
    </inertial>
    <visual>
      <origin xyz="0 0 0" rpy="0 0 0" />
      <geometry>
        <mesh filename="package://spmr02/meshes/base_link.STL" />
      </geometry>
      <material name="">
        <color rgba="0.75294 0.75294 0.75294 1" />
      </material>
    </visual>
    <collision>
      <origin xyz="0 0 0" rpy="0 0 0" />
      <geometry>
        <mesh filename="package://spmr02/meshes/base_link.STL" />
      </geometry>
    </collision>
    <surface>
      <friction>
        <ode>
          <mu>0.001</mu>
          <mu2>0.001</mu2>
        </ode>
      </friction>
    </surface>
  </link>
  <link name="right_wheel_link">
    <inertial>
      <origin xyz="0.83427 1.2432E-08 1.1348E-14" rpy="0 0 0" />
      <mass value="2.0043" />
      <inertia ixx="0.020935" ixy="1.5041E-10" ixz="1.4232E-17" iyy="0.010841" iyz="8.1024E-19" izz="0.010841" />
    </inertial>
    <visual>
      <origin xyz="0 0 0" rpy="0 0 0" />
      <geometry>
        <mesh filename="package://spmr02/meshes/right_wheel_link.STL" />
      </geometry>
      <material name="">
        <color rgba="0.75294 0.75294 0.75294 1" />
      </material>
    </visual>
    <collision>
      <origin xyz="0 0 0" rpy="0 0 0" />
      <geometry>
        <mesh filename="package://spmr02/meshes/right_wheel_link.STL" />
      </geometry>
    </collision>
  </link>
  <joint name="right_wheel_joint" type="continuous">
    <origin xyz="0 0.40407 -0.001" rpy="1.5708 0 -1.5708" />
    <parent link="base_link" />
    <child link="right_wheel_link" />
    <axis xyz="-1 0 0" />
  </joint>
  <link name="left_wheel_link">
    <inertial>
      <origin xyz="0.83427 2.7462E-14 -1.1491E-14" rpy="0 0 0" />
      <mass value="2.0043" />
      <inertia ixx="0.020935" ixy="3.6958E-18" ixz="1.3244E-17" iyy="0.010841" iyz="4.6529E-19" izz="0.010841" />
    </inertial>
    <visual>
      <origin xyz="0 0 0" rpy="0 0 0" />
      <geometry>
        <mesh filename="package://spmr02/meshes/left_wheel_link.STL" />
      </geometry>
      <material name="">
        <color rgba="0.75294 0.75294 0.75294 1" />
      </material>
    </visual>
    <collision>
      <origin xyz="0 0 0" rpy="0 0 0" />
      <geometry>
        <mesh filename="package://spmr02/meshes/left_wheel_link.STL" />
      </geometry>
    </collision>
  </link>
  <joint name="left_wheel_joint" type="continuous">
    <origin xyz="0 -0.40407 -0.001" rpy="1.5708 0 1.5708" />
    <parent link="base_link" />
    <child link="left_wheel_link" />
    <axis xyz="1 0 0" />
  </joint>



  <link name="RF_scan_link">
    <inertial>
      <origin xyz="0.17357 -0.079376 -1.5775" rpy="0 0 0" />
      <mass value="0.008" />
      <inertia ixx="5.0999E-07" ixy="7.1237E-09" ixz="5.8864E-08" iyy="1.2827E-06" iyz="-7.8405E-08" izz="1.0187E-06" />
    </inertial>
    <visual>
      <origin xyz="0 0 0" rpy="0 0 0" />
      <geometry>
        <mesh filename="package://spmr02/meshes/RF_scan_link.STL" />
      </geometry>
      <material name="">
        <color rgba="0.75294 0.75294 0.75294 1" />
      </material>
    </visual>
    <collision>
      <origin xyz="0 0 0" rpy="0 0 0" />
      <geometry>
        <mesh filename="package://spmr02/meshes/RF_scan_link.STL" />
      </geometry>
    </collision>
  </link>


  <joint name="RF_scan_joint" type="fixed">
    <origin xyz="-0.63018 0.50694 -0.10141" rpy="-1.5708 0 0.7854" />
    <parent link="base_link" />
    <child link="RF_scan_link" />
    <axis xyz="0 0 0" />
  </joint>



  <link name="LR_scan_link">
    <inertial>
      <origin xyz="0.20435 -0.079376 -1.5302" rpy="0 0 0" />
      <mass value="0.008" />
      <inertia ixx="5.0999E-07" ixy="7.1237E-09" ixz="5.8864E-08" iyy="1.2827E-06" iyz="-7.8405E-08" izz="1.0187E-06" />
    </inertial>
    <visual>
      <origin xyz="0 0 0" rpy="0 0 0" />
      <geometry>
        <mesh filename="package://spmr02/meshes/LR_scan_link.STL" />
      </geometry>
      <material name="">
        <color rgba="0.75294 0.75294 0.75294 1" />
      </material>
    </visual>
    <collision>
      <origin xyz="0 0 0" rpy="0 0 0" />
      <geometry>
        <mesh filename="package://spmr02/meshes/LR_scan_link.STL" />
      </geometry>
    </collision>
  </link>


  <joint name="LR_scan_joint" type="fixed">
    <origin xyz="0.61848 -0.45171 -0.10141" rpy="-1.5708 0 -2.3562" />
    <parent link="base_link" />
    <child link="LR_scan_link" />
    <axis xyz="0 0 0" />
  </joint>


  <gazebo>
    <plugin name="gazebo_ros_control" filename="libgazebo_ros_control.so">
      <robotNamespace>/spmr02</robotNamespace>
    </plugin>

    <plugin name="differential_drive_controller" filename="libgazebo_ros_diff_drive.so">
      <alwaysOn>true</alwaysOn>
      <updateRate>100</updateRate>
      <rosDebugLevel>1</rosDebugLevel>
      <leftJoint>left_wheel_joint</leftJoint>
      <rightJoint>right_wheel_joint</rightJoint>
      <torque>500</torque>
      <commandTopic>spmr/cmd_val</commandTopic>
      <odometryTopic>/odom</odometryTopic>
      <odometryFrame>odom</odometryFrame>
      <publishTf>1</publishTf>
      <publishWheelTF>0</publishWheelTF>
      <publishOdomTF>0</publishOdomTF>
      <publishWheelJointState>1</publishWheelJointState>
      <wheelAcceleration>1</wheelAcceleration>
      <wheelTorque>500</wheelTorque>
      <odometrySource>world</odometrySource>
      <robotBaseFrame>base_link</robotBaseFrame>
      <wheelSeparation>0.8</wheelSeparation>
      <wheelDiameter>0.265</wheelDiameter>
    </plugin>

  </gazebo>

  <gazebo reference="RF_scan_link">
    <material value="Gazebo/Red" />
    <sensor type="ray" name="RF_scan">
      <always_on>true</always_on>
      <update_rate>10</update_rate>
      <pose>0 0 0 0 0 0</pose>
      <visualize>1</visualize>
      <ray>
        <scan>
          <horizontal>
            <samples>271</samples>
            <resolution>1</resolution>
            <min_angle>-2.35619449019</min_angle>
            <max_angle>2.35619449019</max_angle>
          </horizontal>
        </scan>
        <range>
          <min>0.05</min>
          <max>25.0</max>
          <resolution>0.01</resolution>
        </range>
      </ray>
      <plugin name="gazebo_ros_RF_scan_controller" filename="libgazebo_ros_laser.so">
        <gaussianNoise>0.005</gaussianNoise>
        <alwaysOn>true</alwaysOn>
        <updateRate>10</updateRate>
        <topicName>/RF_scan</topicName>
        <frameName>RF_scan_frame</frameName>
      </plugin>
    </sensor>
  </gazebo>

  <gazebo reference="LR_scan_link">
    <material value="Gazebo/Blue" />
    <sensor type="ray" name="LR_scan">
      <always_on>true</always_on>
      <update_rate>10</update_rate>
      <pose>0 0 0 0 0 0</pose>
      <visualize>1</visualize>
      <ray>
        <scan>
          <horizontal>
            <samples>271</samples>
            <resolution>1</resolution>
            <min_angle>-2.35619449019</min_angle>
            <max_angle>2.35619449019</max_angle>
          </horizontal>
        </scan>
        <range>
          <min>0.05</min>
          <max>25.0</max>
          <resolution>0.01</resolution>
        </range>
      </ray>
      <plugin name="gazebo_ros_LR_scan_controller" filename="libgazebo_ros_laser.so">
        <gaussianNoise>0.005</gaussianNoise>
        <alwaysOn>true</alwaysOn>
        <updateRate>10</updateRate>
        <topicName>/LR_scan</topicName>
        <frameName>LR_scan_frame</frameName>
      </plugin>
    </sensor>
  </gazebo>

</robot>